{
 "cells": [
  {
   "cell_type": "markdown",
   "metadata": {},
   "source": [
    "# 8. 错误和异常\n",
    "到目前为止，我们还没有提到错误消息，但是如果你已经尝试过那些例子，你可能已经看过了一些错误消息。 目前（至少）有两种可区分的错误：语法错误 和 异常。\n",
    "\n",
    "## 8.1. 语法错误\n",
    "语法错误又称解析错误，可能是你在学习Python 时最容易遇到的错误:"
   ]
  },
  {
   "cell_type": "code",
   "execution_count": null,
   "metadata": {},
   "outputs": [],
   "source": [
    "while True print('Hello world')\n",
    "  File \"<stdin>\", line 1\n",
    "    while True print('Hello world')\n",
    "                   ^\n",
    "SyntaxError: invalid syntax"
   ]
  },
  {
   "cell_type": "markdown",
   "metadata": {},
   "source": [
    "解析器会输出出现语法错误的那一行，并显示一个“箭头”，指向这行里面检测到第一个错误。 错误是由箭头指示的位置 上面 的 token 引起的（或者至少是在这里被检测出的）：在示例中，在 print() 这个函数中检测到了错误，因为在它前面少了个冒号 (':') 。文件名和行号也会被输出，以便输入来自脚本文件时你能知道去哪检查。\n",
    "\n",
    "## 8.2. 异常\n",
    "即使语句或表达式在语法上是正确的，但在尝试执行时，它仍可能会引发错误。 在执行时检测到的错误被称为*异常*，异常不一定会导致严重后果：你将很快学会如何在Python程序中处理它们。 但是，大多数异常并不会被程序处理，此时会显示如下所示的错误信息:"
   ]
  },
  {
   "cell_type": "code",
   "execution_count": null,
   "metadata": {},
   "outputs": [],
   "source": [
    "10 * (1/0)\n",
    "\n",
    "\n",
    "4 + spam*3\n",
    "\n",
    "\n",
    "'2' + 2\n"
   ]
  },
  {
   "cell_type": "markdown",
   "metadata": {},
   "source": [
    "错误信息的最后一行告诉我们程序遇到了什么类型的错误。异常有不同的类型，而其类型名称将会作为错误信息的一部分中打印出来：上述示例中的异常类型依次是：ZeroDivisionError， NameError 和 TypeError。作为异常类型打印的字符串是发生的内置异常的名称。对于所有内置异常都是如此，但对于用户定义的异常则不一定如此（虽然这是一个有用的规范）。标准的异常类型是内置的标识符（而不是保留关键字）。\n",
    "\n",
    "这一行的剩下的部分根据异常类型及其原因提供详细信息。\n",
    "\n",
    "错误信息的前一部分以堆栈回溯的形式显示发生异常时的上下文。通常它包含列出源代码行的堆栈回溯；但是它不会显示从标准输入中读取的行。\n",
    "\n",
    "[内置异常](https://docs.python.org/zh-cn/3/library/exceptions.html#bltin-exceptions) 列出了内置异常和它们的含义。\n",
    "\n",
    "## 8.3. 处理异常\n",
    "可以编写处理所选异常的程序。请看下面的例子，它会要求用户一直输入，直到输入的是一个有效的整数，但允许用户中断程序（使用 Control-C 或操作系统支持的其他操作）；请注意用户引起的中断可以通过引发 [KeyboardInterrupt](https://docs.python.org/zh-cn/3/library/exceptions.html#KeyboardInterrupt) 异常来指示。:"
   ]
  },
  {
   "cell_type": "code",
   "execution_count": null,
   "metadata": {},
   "outputs": [],
   "source": [
    "while True:\n",
    "    try:\n",
    "        x = int(input(\"Please enter a number: \"))\n",
    "        break\n",
    "    except ValueError:\n",
    "        print(\"Oops!  That was no valid number.  Try again...\")\n"
   ]
  },
  {
   "cell_type": "markdown",
   "metadata": {},
   "source": [
    "[try](https://docs.python.org/zh-cn/3/reference/compound_stmts.html#try) 语句的工作原理如下。\n",
    "\n",
    "* 首先，执行 try 子句 （[try](https://docs.python.org/zh-cn/3/reference/compound_stmts.html#try) 和 [except](https://docs.python.org/zh-cn/3/reference/compound_stmts.html#except) 关键字之间的（多行）语句）。\n",
    "\n",
    "* 如果没有异常发生，则跳过 except 子句 并完成 try 语句的执行。\n",
    "\n",
    "* 如果在执行try 子句时发生了异常，则跳过该子句中剩下的部分。然后，如果异常的类型和 except 关键字后面的异常匹配，则执行 except 子句 ，然后继续执行 try 语句之后的代码。\n",
    "\n",
    "* 如果发生的异常和 except 子句中指定的异常不匹配，则将其传递到外部的 try 语句中；如果没有找到处理程序，则它是一个 未处理异常，执行将停止并显示如上所示的消息。\n",
    "\n",
    "一个 try 语句可能有多个 except 子句，以指定不同异常的处理程序。 最多会执行一个处理程序。 处理程序只处理相应的 try 子句中发生的异常，而不处理同一 try 语句内其他处理程序中的异常。 一个 except 子句可以将多个异常命名为带括号的元组，例如:"
   ]
  },
  {
   "cell_type": "code",
   "execution_count": null,
   "metadata": {},
   "outputs": [],
   "source": [
    "... except (RuntimeError, TypeError, NameError):\n",
    "...     pass"
   ]
  },
  {
   "cell_type": "markdown",
   "metadata": {},
   "source": [
    "如果发生的异常和 except 子句中的类是同一个类或者是它的基类，则异常和except子句中的类是兼容的（但反过来则不成立 --- 列出派生类的except 子句与基类兼容）。例如，下面的代码将依次打印 B, C, D"
   ]
  },
  {
   "cell_type": "code",
   "execution_count": null,
   "metadata": {},
   "outputs": [],
   "source": [
    "class B(Exception):\n",
    "    pass\n",
    "\n",
    "class C(B):\n",
    "    pass\n",
    "\n",
    "class D(C):\n",
    "    pass\n",
    "\n",
    "for cls in [B, C, D]:\n",
    "    try:\n",
    "        raise cls()\n",
    "    except D:\n",
    "        print(\"D\")\n",
    "    except C:\n",
    "        print(\"C\")\n",
    "    except B:\n",
    "        print(\"B\")"
   ]
  },
  {
   "cell_type": "markdown",
   "metadata": {},
   "source": [
    "请注意如果 except 子句被颠倒（把 except B 放到第一个），它将打印 B，B，B --- 即第一个匹配的 except 子句被触发。\n",
    "\n",
    "最后的 except 子句可以省略异常名，以用作通配符。但请谨慎使用，因为以这种方式很容易掩盖真正的编程错误！它还可用于打印错误消息，然后重新引发异常（同样允许调用者处理异常）:"
   ]
  },
  {
   "cell_type": "code",
   "execution_count": null,
   "metadata": {},
   "outputs": [],
   "source": [
    "import sys\n",
    "\n",
    "try:\n",
    "    f = open('myfile.txt')\n",
    "    s = f.readline()\n",
    "    i = int(s.strip())\n",
    "except OSError as err:\n",
    "    print(\"OS error: {0}\".format(err))\n",
    "except ValueError:\n",
    "    print(\"Could not convert data to an integer.\")\n",
    "except:\n",
    "    print(\"Unexpected error:\", sys.exc_info()[0])\n",
    "    raise"
   ]
  },
  {
   "cell_type": "markdown",
   "metadata": {},
   "source": [
    "try ... except 语句有一个可选的 else 子句，在使用时必须放在所有的 except 子句后面。对于在try 子句不引发异常时必须执行的代码来说很有用。例如:"
   ]
  },
  {
   "cell_type": "code",
   "execution_count": null,
   "metadata": {},
   "outputs": [],
   "source": [
    "for arg in sys.argv[1:]:\n",
    "    try:\n",
    "        f = open(arg, 'r')\n",
    "    except OSError:\n",
    "        print('cannot open', arg)\n",
    "    else:\n",
    "        print(arg, 'has', len(f.readlines()), 'lines')\n",
    "        f.close()"
   ]
  },
  {
   "cell_type": "markdown",
   "metadata": {},
   "source": [
    "使用 else 子句比向 try 子句添加额外的代码要好，因为它避免了意外捕获由 try ... except 语句保护的代码未引发的异常。\n",
    "\n",
    "发生异常时，它可能具有关联值，也称为异常 参数 。参数的存在和类型取决于异常类型。\n",
    "\n",
    "except 子句可以在异常名称后面指定一个变量。这个变量和一个异常实例绑定，它的参数存储在 instance.args 中。为了方便起见，异常实例定义了 __str__() ，因此可以直接打印参数而无需引用 .args 。也可以在抛出之前首先实例化异常，并根据需要向其添加任何属性。:"
   ]
  },
  {
   "cell_type": "code",
   "execution_count": null,
   "metadata": {},
   "outputs": [],
   "source": [
    "try:\n",
    "    raise Exception('spam', 'eggs')\n",
    "except Exception as inst:\n",
    "    print(type(inst))    # the exception instance\n",
    "    print(inst.args)     # arguments stored in .args\n",
    "    print(inst)          # __str__ allows args to be printed directly,\n",
    "                         # but may be overridden in exception subclasses\n",
    "    x, y = inst.args     # unpack args\n",
    "    print('x =', x)\n",
    "    print('y =', y)"
   ]
  },
  {
   "cell_type": "markdown",
   "metadata": {},
   "source": [
    "如果异常有参数，则它们将作为未处理异常的消息的最后一部分（'详细信息'）打印。\n",
    "\n",
    "异常处理程序不仅处理 try 子句中遇到的异常，还处理 try 子句中调用（即使是间接地）的函数内部发生的异常。例如:"
   ]
  },
  {
   "cell_type": "code",
   "execution_count": null,
   "metadata": {},
   "outputs": [],
   "source": [
    "def this_fails():\n",
    "    x = 1/0\n",
    "\n",
    "try:\n",
    "    this_fails()\n",
    "except ZeroDivisionError as err:\n",
    "    print('Handling run-time error:', err)"
   ]
  },
  {
   "cell_type": "markdown",
   "metadata": {},
   "source": [
    "## 8.4. 抛出异常 \n",
    "[raise](https://docs.python.org/zh-cn/3/reference/simple_stmts.html#raise) 语句允许程序员强制发生指定的异常。例如:"
   ]
  },
  {
   "cell_type": "code",
   "execution_count": null,
   "metadata": {},
   "outputs": [],
   "source": [
    "raise NameError('HiThere')"
   ]
  },
  {
   "cell_type": "markdown",
   "metadata": {},
   "source": [
    "raise 唯一的参数就是要抛出的异常。这个参数必须是一个异常实例或者是一个异常类（派生自 [Exception](https://docs.python.org/zh-cn/3/library/exceptions.html#Exception) 的类）。如果传递的是一个异常类，它将通过调用没有参数的构造函数来隐式实例化:"
   ]
  },
  {
   "cell_type": "code",
   "execution_count": null,
   "metadata": {},
   "outputs": [],
   "source": [
    "raise ValueError  # shorthand for 'raise ValueError()'"
   ]
  },
  {
   "cell_type": "markdown",
   "metadata": {},
   "source": [
    "如果你需要确定是否引发了异常但不打算处理它，则可以使用更简单的 raise 语句形式重新引发异常"
   ]
  },
  {
   "cell_type": "code",
   "execution_count": null,
   "metadata": {},
   "outputs": [],
   "source": [
    "try:\n",
    "    raise NameError('HiThere')\n",
    "except NameError:\n",
    "    print('An exception flew by!')\n",
    "    raise"
   ]
  },
  {
   "cell_type": "markdown",
   "metadata": {},
   "source": [
    "## 8.5. 用户自定义异常 \n",
    "程序可以通过创建新的异常类来命名它们自己的异常（有关Python 类的更多信息，请参阅 类）。异常通常应该直接或间接地从 Exception 类派生。\n",
    "\n",
    "可以定义异常类，它可以执行任何其他类可以执行的任何操作，但通常保持简单，通常只提供许多属性，这些属性允许处理程序为异常提取有关错误的信息。在创建可能引发多个不同错误的模块时，通常的做法是为该模块定义的异常创建基类，并为不同错误条件创建特定异常类的子类:"
   ]
  },
  {
   "cell_type": "code",
   "execution_count": null,
   "metadata": {},
   "outputs": [],
   "source": [
    "class Error(Exception):\n",
    "    \"\"\"Base class for exceptions in this module.\"\"\"\n",
    "    pass\n",
    "\n",
    "class InputError(Error):\n",
    "    \"\"\"Exception raised for errors in the input.\n",
    "\n",
    "    Attributes:\n",
    "        expression -- input expression in which the error occurred\n",
    "        message -- explanation of the error\n",
    "    \"\"\"\n",
    "\n",
    "    def __init__(self, expression, message):\n",
    "        self.expression = expression\n",
    "        self.message = message\n",
    "\n",
    "class TransitionError(Error):\n",
    "    \"\"\"Raised when an operation attempts a state transition that's not\n",
    "    allowed.\n",
    "\n",
    "    Attributes:\n",
    "        previous -- state at beginning of transition\n",
    "        next -- attempted new state\n",
    "        message -- explanation of why the specific transition is not allowed\n",
    "    \"\"\"\n",
    "\n",
    "    def __init__(self, previous, next, message):\n",
    "        self.previous = previous\n",
    "        self.next = next\n",
    "        self.message = message"
   ]
  },
  {
   "cell_type": "markdown",
   "metadata": {},
   "source": [
    "大多数异常都定义为名称以“Error”结尾，类似于标准异常的命名。\n",
    "\n",
    "许多标准模块定义了它们自己的异常，以报告它们定义的函数中可能出现的错误。有关类的更多信息，请参见类 类。\n",
    "\n",
    "## 8.6. 定义清理操作\n",
    "try 语句有另一个可选子句，用于定义必须在所有情况下执行的清理操作。例如:"
   ]
  },
  {
   "cell_type": "code",
   "execution_count": null,
   "metadata": {},
   "outputs": [],
   "source": [
    "try:\n",
    "    raise KeyboardInterrupt\n",
    "finally:\n",
    "    print('Goodbye, world!')\n",
    "KeyboardInterrupt"
   ]
  },
  {
   "cell_type": "markdown",
   "metadata": {},
   "source": [
    "If a finally clause is present, the finally clause will execute as the last task before the try statement completes. The finally clause runs whether or not the try statement produces an exception. The following points discuss more complex cases when an exception occurs:\n",
    "\n",
    "* If an exception occurs during execution of the try clause, the exception may be handled by an except clause. If the exception is not handled by an except clause, the exception is re-raised after the finally clause has been executed.\n",
    "\n",
    "* An exception could occur during execution of an except or else clause. Again, the exception is re-raised after the finally clause has been executed.\n",
    "\n",
    "* If the try statement reaches a break, continue or return statement, the finally clause will execute just prior to the break, continue or return statement's execution.\n",
    "\n",
    "* If a finally clause includes a return statement, the finally clause's return statement will execute before, and instead of, the return statement in a try clause.\n",
    "\n",
    "For example:"
   ]
  },
  {
   "cell_type": "code",
   "execution_count": null,
   "metadata": {},
   "outputs": [],
   "source": [
    "def bool_return():\n",
    "    try:\n",
    "        return True\n",
    "    finally:\n",
    "        return False\n",
    "\n",
    "bool_return()"
   ]
  },
  {
   "cell_type": "markdown",
   "metadata": {},
   "source": [
    "A more complicated example:"
   ]
  },
  {
   "cell_type": "code",
   "execution_count": null,
   "metadata": {},
   "outputs": [],
   "source": [
    "def divide(x, y):\n",
    "    try:\n",
    "        result = x / y\n",
    "    except ZeroDivisionError:\n",
    "        print(\"division by zero!\")\n",
    "    else:\n",
    "        print(\"result is\", result)\n",
    "    finally:\n",
    "        print(\"executing finally clause\")\n",
    "\n",
    "divide(2, 1)\n",
    "divide(2, 0)\n",
    "divide(\"2\", \"1\")"
   ]
  },
  {
   "cell_type": "markdown",
   "metadata": {},
   "source": [
    "正如你所看到的，[finally](https://docs.python.org/zh-cn/3/reference/compound_stmts.html#finally) 子句在任何情况下都会被执行。 两个字符串相除所引发的 TypeError 不会由 except 子句处理，因此会在 finally 子句执行后被重新引发。\n",
    "\n",
    "在实际应用程序中，finally 子句对于释放外部资源（例如文件或者网络连接）非常有用，无论是否成功使用资源。\n",
    "\n",
    "## 8.7. 预定义的清理操作\n",
    "某些对象定义了在不再需要该对象时要执行的标准清理操作，无论使用该对象的操作是成功还是失败。请查看下面的示例，它尝试打开一个文件并把其内容打印到屏幕上。:"
   ]
  },
  {
   "cell_type": "code",
   "execution_count": null,
   "metadata": {},
   "outputs": [],
   "source": [
    "for line in open(\"myfile.txt\"):\n",
    "    print(line, end=\"\")"
   ]
  },
  {
   "cell_type": "markdown",
   "metadata": {},
   "source": [
    "这个代码的问题在于，它在这部分代码执行完后，会使文件在一段不确定的时间内处于打开状态。这在简单脚本中不是问题，但对于较大的应用程序来说可能是个问题。 with 语句允许像文件这样的对象能够以一种确保它们得到及时和正确的清理的方式使用。:"
   ]
  },
  {
   "cell_type": "code",
   "execution_count": null,
   "metadata": {},
   "outputs": [],
   "source": [
    "with open(\"myfile.txt\") as f:\n",
    "    for line in f:\n",
    "        print(line, end=\"\")"
   ]
  },
  {
   "cell_type": "markdown",
   "metadata": {},
   "source": [
    "执行完语句后，即使在处理行时遇到问题，文件 f 也始终会被关闭。和文件一样，提供预定义清理操作的对象将在其文档中指出这一点。\n"
   ]
  }
 ],
 "metadata": {
  "kernelspec": {
   "display_name": "Python 3",
   "language": "python",
   "name": "python3"
  },
  "language_info": {
   "codemirror_mode": {
    "name": "ipython",
    "version": 3
   },
   "file_extension": ".py",
   "mimetype": "text/x-python",
   "name": "python",
   "nbconvert_exporter": "python",
   "pygments_lexer": "ipython3",
   "version": "3.7.3"
  }
 },
 "nbformat": 4,
 "nbformat_minor": 2
}
